Workbook

Sheet Main
A1: Movie Name | B1: Scraped Name | C1: Budget | D1: Director | E1: Writer | F1: Actor | G1: Rating | H1: OtherInfo | I1: Date | J1: DirectorsRating | K1: WritersRating | L1: TotalFollowers | M1: Revenue
A2: Foodfight! | B2: Foodfight! | C2: 45000000 | D2: ['Lawrence Kasanoff'] | E2: ['Lawrence Kasanoff', 'Joshua Wexler', 'Brent V. Friedman'] | F2: ['Hilary Duff', 'Haylie Duff', 'Charlie Sheen'] | G2: 1.3 | H2: 2012 PG 1h 31m | I2: 2012 | J2: 1 | K2: 1.6666667 | L2: 18.30103 | M2: =_xlfn.XLOOKUP(A2,Revenue!A:A,Revenue!C:C) -> 120323
A3: Superbabies: Baby Geniuses 2 | B3: Superbabies: Baby Geniuses 2 | C3: 20000000 | D3: ['Bob Clark'] | E3: ['Robert Grasmere', 'Francisca Matos', 'Steven Paul'] | F3: ['Jon Voight', 'Scott Baio', 'Vanessa Angel'] | G3: 1.5 | H3: 2004 PG 1h 28m | I3: 2004 | J3: 7 | K3: 1.5 | L3: 7.6825602 | M3: =_xlfn.XLOOKUP(A3,Revenue!A:A,Revenue!C:C) -> 9355369
A4: The Oogieloves in the BIG Balloon Adventure | B4: The Oogieloves in the Big Balloon Adventure | C4: 20000000 | D4: ['Matthew Diamond'] | E4: ['Scott Stabile', 'Kenn Viselman', 'Alex J Greene'] | F4: ['Jaime Pressly', 'Cloris Leachman', 'Christopher Lloyd'] | G4: 1.7 | H4: 2012 G 1h 28m | I4: 2012 | J4: 1 | K4: 1 | L4: 11.450043 | M4: =_xlfn.XLOOKUP(A4,Revenue!A:A,Revenue!C:C) -> 1065907
A5: Justin Bieber: Never Say Never | B5: Justin Bieber: Never Say Never | C5: 13000000 | D5: ['Jon M. Chu'] | E5: ['Justin Bieber', 'Boyz II Men', 'Miley Cyrus'] | F5: ['Justin Bieber', 'Boyz II Men', 'Miley Cyrus'] | G5: 1.7 | H5: 2011 G 1h 45m | I5: 2011 | J5: 6.3333333 | K5: 1 | L5: 20.045591 | M5: =_xlfn.XLOOKUP(A5,Revenue!A:A,Revenue!C:C) -> 99034125
A6: Disaster Movie | B6: Disaster Movie | C6: 20000000 | D6: ['Jason Friedberg', 'Aaron Seltzer'] | E6: ['Jason Friedberg', 'Aaron Seltzer'] | F6: ['Carmen Electra', 'Vanessa Lachey', 'Nicole Parker'] | G6: 1.9 | H6: 2008 PG-13 1h 27m | I6: 2008 | J6: 2.3333333 | K6: 3.3333333 | L6: 18.60206 | M6: =_xlfn.XLOOKUP(A6,Revenue!A:A,Revenue!C:C) -> 36720752
A7: From Justin to Kelly | B7: From Justin to Kelly | C7: 12000000 | D7: ['Robert Iscove'] | E7: ['Kim Fuller'] | F7: ['Kelly Clarkson', 'Justin Guarini', 'Katherine Bailess'] | G7: 1.9 | H7: 2003 PG 1h 21m | I7: 2003 | J7: 3.6666667 | K7: 3.3333333 | L7: 15.090628 | M7: =_xlfn.XLOOKUP(A7,Revenue!A:A,Revenue!C:C) -> 4922166
A8: United Passions | B8: United Passions | C8: 30000000 | D8: ['Fr√É¬©d√É¬©ric Auburtin'] | E8: ['Fr√É¬©d√É¬©ric Auburtin', 'Jean-Paul Delfino'] | F8: ['G√É¬©rard Depardieu', 'Sam Neill', 'Tim Roth'] | G8: 2.1 | H8: 2014 Not Rated 1h 50m | I8: 2014 | J8: 4.5 | K8: 2 | L8: 10.39238 | M8: =_xlfn.XLOOKUP(A8,Revenue!A:A,Revenue!C:C) -> 168832
A9: House of the Dead | B9: House of the Dead | C9: 7000000 | D9: ['Uwe Boll'] | E9: ['Mark A. Altman', 'Dan Bates', 'Dave Parker'] | F9: ['Jonathan Cherry', 'Tyron Leitso', 'Clint Howard'] | G9: 2.1 | H9: 2003 R 1h 30m | I9: 2003 | J9: 2.6666667 | K9: 2 | L9: 10.953115 | M9: =_xlfn.XLOOKUP(A9,Revenue!A:A,Revenue!C:C) -> 13860078
A10: The Helix√É¬¢√Ç¬Ä√Ç¬¶Loaded | B10: The Helix... Loaded | C10: 1000000 | D10: ['A. Raven Cruz'] | E10: ['A. Raven Cruz'] | F10: ['Scott Levy', 'Vanilla Ice', 'Geremy Dingle'] | G10: 2.1 | H10: 2005 R 1h 37m | I10: 2005 | J10: 2 | K10: 2 | L10: 10.953004 | M10: =_xlfn.XLOOKUP(A10,Revenue!A:A,Revenue!C:C) -> #N/A
A11: Son of the Mask | B11: Son of the Mask | C11: 100000000 | D11: ['Lawrence Guterman'] | E11: ['Lance Khazei'] | F11: ['Jamie Kennedy', 'Traylor Howard', 'Alan Cumming'] | G11: 2.2 | H11: 2005 PG 1h 34m | I11: 2005 | J11: 3.5 | K11: 2 | L11: 14.53559 | M11: =_xlfn.XLOOKUP(A11,Revenue!A:A,Revenue!C:C) -> 59918422
A12: Who's Your Caddy? | B12: Who's Your Caddy? | C12: 7000000 | D12: ['Don Michael Paul'] | E12: ['Don Michael Paul', 'Bradley Allenstein', 'Robert Henny'] | F12: ['Big Boi', 'Jeffrey Jones', 'Terry Crews'] | G12: 2.2 | H12: 2007 PG-13 1h 33m | I12: 2007 | J12: 3 | K12: 3 | L12: 13.30103 | M12: =_xlfn.XLOOKUP(A12,Revenue!A:A,Revenue!C:C) -> 5694308
A13: Rock the House | B13: De Bellinga's: Huis op stelten | C13: 250000 | D13: ['Armando de Boer'] | E13: ['Martijn Koevoets'] | F13: ['Luan Bellinga', 'Lucilla Bellinga', 'Dani√É¬´l Bellinga'] | G13: 2.2 | H13: 2022 1h 5m | I13: 2022 | J13: 2 | K13: 2 | L13: 9.5317343 | M13: =_xlfn.XLOOKUP(A13,Revenue!A:A,Revenue!C:C) -> 0
... A644: Stung | B644: Stung | C644: 2500000 | D644: ['Benni Diez'] | E644: ['Adam Aresty'] | F644: ['Matt O Leary', 'Jessica Cook', 'Lance Henriksen'] | G644: 5.1 | H644: 2015 Not Rated 1h 27m | I644: 2015 | J644: 5 | K644: 5 | L644: 8.1556761 | M644: =_xlfn.XLOOKUP(A644,Revenue!A:A,Revenue!C:C) -> 0
A645: Captive | B645: Captive | C645: 2000000 | D645: ['Gregg Simon'] | E645: ['Travis Seppala'] | F645: ['Scout Taylor-Compton', 'Brendan Fehr', 'Tasie Lawrence'] | G645: 5.1 | H645: 2023 | I645: 2023 | J645: 5 | K645: 5 | L645: 14.654173 | M645: =_xlfn.XLOOKUP(A645,Revenue!A:A,Revenue!C:C) -> 2791973
A646: This Thing of Ours | B646: This Thing of Ours | C646: 2000000 | D646: ['Danny Provenzano'] | E646: ['Ted A. Bohus', 'Danny Provenzano'] | F646: ['Frank Vincent', 'Vincent Pastore', 'Louis Vanaria'] | G646: 5.1 | H646: 2002 Not Rated 1h 40m | I646: 2002 | J646: 5 | K646: 5 | L646: 6.8454435 | M646: =_xlfn.XLOOKUP(A646,Revenue!A:A,Revenue!C:C) -> 37227
A647: Lesbian Vampire Killers | B647: Vampire Killers | C647: 2000000 | D647: ['Phil Claydon'] | E647: ['Stewart Williams', 'Paul Hupfield'] | F647: ['Paul McGann', 'James Corden', 'MyAnna Buring'] | G647: 5.1 | H647: 2009 R 1h 26m | I647: 2009 | J647: 5 | K647: 5 | L647: 13.262839 | M647: =_xlfn.XLOOKUP(A647,Revenue!A:A,Revenue!C:C) -> 3620902
A648: Living Dark: The Story of Ted the Caver | B648: Living Dark: The Story of Ted the Caver | C648: 1750000 | D648: ['David L. Hunt'] | E648: ['David L. Hunt', 'Kevin Brown'] | F648: ['Chris Cleveland', 'Matthew Alan', 'Mark Hayter'] | G648: 5.1 | H648: 2013 PG-13 1h 52m | I648: 2013 | J648: 6 | K648: 5.5 | L648: 3.1705551 | M648: =_xlfn.XLOOKUP(A648,Revenue!A:A,Revenue!C:C) -> 0
A649: Kiljuset! | B649: Kiljuset! | C649: 1606057 | D649: ['Reetta Huhtanen'] | E649: ['Jenny Dahlstr√É¬∂m', 'Jalmari Finne', 'John Lundsten'] | F649: ['Jaakko Hutchings', 'Hugo Koivulehto', 'Nino Kr√É¬∂ger'] | G649: 5.1 | H649: 2022 1h 23m | I649: 2022 | J649: 5 | K649: 5 | L649: 1.9777236 | M649: =_xlfn.XLOOKUP(A649,Revenue!A:A,Revenue!C:C) -> 1029483
A650: I Love Your Work | B650: I Love Your Work | C650: 1600000 | D650: ['Adam Goldberg'] | E650: ['Adrian Butchart', 'Adam Goldberg'] | F650: ['Marisa Coughlan', 'Judy Greer', 'Shalom Harlow'] | G650: 5.1 | H650: 2003 R 1h 51m | I650: 2003 | J650: 5 | K650: 5.25 | L650: 6.1875563 | M650: =_xlfn.XLOOKUP(A650,Revenue!A:A,Revenue!C:C) -> 3264
A651: 31 | B651: 31 | C651: 1500000 | D651: ['Rob Zombie'] | E651: ['Rob Zombie'] | F651: ['Malcolm McDowell', 'Richard Brake', 'Jeff Daniel Phillips'] | G651: 5.1 | H651: 2016 1h 42m | I651: 2016 | J651: 5.6666667 | K651: 6.3333333 | L651: 14.275778 | M651: =_xlfn.XLOOKUP(A651,Revenue!A:A,Revenue!C:C) -> 922727
A652: Forget Me Not | B652: Forget Me Not | C652: 1300000 | D652: ['Tyler Oliver'] | E652: ['Jamieson Stern', 'Tyler Oliver'] | F652: ['Carly Schroeder', 'Cody Linley', 'Brie Gabrielle'] | G652: 5.1 | H652: 2009 R 1h 43m | I652: 2009 | J652: 5 | K652: 5 | L652: 0 | M652: =_xlfn.XLOOKUP(A652,Revenue!A:A,Revenue!C:C) -> 13465
A653: The Sleepwalker (2014) | B653: The Sleepwalker | C653: 1100000 | D653: ['Mona Fastvold'] | E653: ['Brady Corbet', 'Mona Fastvold'] | F653: ['Gitte Witt', 'Christopher Abbott', 'Stephanie Ellis'] | G653: 5.1 | H653: 2014 Not Rated 1h 31m | I653: 2014 | J653: 5 | K653: 5 | L653: 10.185242 | M653: =_xlfn.XLOOKUP(A653,Revenue!A:A,Revenue!C:C) -> 53240
A654: Escape from Tomorrow | B654: Escape from Tomorrow | C654: 650000 | D654: ['Randy Moore'] | E654: ['Randy Moore'] | F654: ['Roy Abramsohn', 'Elena Schuber', 'Katelynn Rodriguez'] | G654: 5.1 | H654: 2013 Not Rated 1h 30m | I654: 2013 | J654: 5 | K654: 5 | L654: 3.6844863 | M654: =_xlfn.XLOOKUP(A654,Revenue!A:A,Revenue!C:C) -> 171962
A655: Civil Brand | B655: Civil Brand | C655: 500000 | D655: ['Neema Barnette'] | E655: ['Preston A. Whitmore II', 'Joyce Renee Lewis'] | F655: ['LisaRaye McCoy', 'N'Bushe Wright', 'Yasiin Bey'] | G655: 5.1 | H655: 2002 R 1h 35m | I655: 2002 | J655: 5 | K655: 5.1666667 | L655: 13.517671 | M655: =_xlfn.XLOOKUP(A655,Revenue!A:A,Revenue!C:C) -> 254293
A656: Love in the Time of Monsters | B656: Love in the Time of Monsters | C656: 500000 | D656: ['Matt Jackson'] | E656: ['Michael Skvarla'] | F656: ['Gena Shaw', 'Kane Hodder', 'Marissa Skell'] | G656: 5.1 | H656: 2014 Not Rated 1h 37m | I656: 2014 | J656: 5 | K656: 5 | L656: 4.603415 | M656: =_xlfn.XLOOKUP(A656,Revenue!A:A,Revenue!C:C) -> 0
A657: Yesterday Was a Lie | B657: Yesterday Was a Lie | C657: 200000 | D657: ['James Kerwin'] | E657: ['James Kerwin'] | F657: ['Kipleigh Brown', 'Chase Masterson', 'John Newton'] | G657: 5.1 | H657: 2009 PG 1h 29m | I657: 2009 | J657: 5 | K657: 5 | L657: 9.973994 | M657: =_xlfn.XLOOKUP(A657,Revenue!A:A,Revenue!C:C) -> 0
A658: Yesterday Was a Lie | B658: Yesterday Was a Lie | C658: 200000 | D658: ['James Kerwin'] | E658: ['James Kerwin'] | F658: ['Kipleigh Brown', 'Chase Masterson', 'John Newton'] | G658: 5.1 | H658: 2009 PG 1h 29m | I658: 2009 | J658: 5 | K658: 5 | L658: 9.973994 | M658: =_xlfn.XLOOKUP(A658,Revenue!A:A,Revenue!C:C) -> 0
A659: The Mummy: Tomb of the Dragon Emperor | B659: The Mummy: Tomb of the Dragon Emperor | C659: 175000000 | D659: ['Rob Cohen'] | E659: ['Alfred Gough', 'Miles Millar', 'John L. Balderston'] | F659: ['Brendan Fraser', 'Jet Li', 'Maria Bello'] | G659: 5.2 | H659: 2008 PG-13 1h 52m | I659: 2008 | J659: 5.6666667 | K659: 6.2222222 | L659: 10.638459 | M659: =_xlfn.XLOOKUP(A659,Revenue!A:A,Revenue!C:C) -> 405760225
A660: Independence Day: Resurgence | B660: Independence Day: Resurgence | C660: 165000000 | D660: ['Roland Emmerich'] | E660: ['Nicolas Wright', 'James A. Woods', 'Dean Devlin'] | F660: ['Liam Hemsworth', 'Jeff Goldblum', 'Bill Pullman'] | G660: 5.2 | H660: 2016 PG-13 2h | I660: 2016 | J660: 7 | K660: 5.4444444 | L660: 13.591065 | M660: =_xlfn.XLOOKUP(A660,Revenue!A:A,Revenue!C:C) -> 384169424
A661: Ast√É¬É√Ç¬©rix aux Jeux Olympiques | B661: Asterix at the Olympic Games | C661: 113500000 | D661: ['Fr√É¬©d√É¬©ric Forestier', 'Thomas Langmann'] | E661: ['Ren√É¬© Goscinny', 'Albert Uderzo', 'Thomas Langmann'] | F661: ['G√É¬©rard Depardieu', 'Clovis Cornillac', 'Beno√É¬Æt Poelvoorde'] | G661: 5.2 | H661: 2008 Not Rated 1h 56m | I661: 2008 | J661: 5 | K661: 5 | L661: 3.6022771 | M661: =_xlfn.XLOOKUP(A661,Revenue!A:A,Revenue!C:C) -> #N/A
A662: A Good Day to Die Hard | B662: A Good Day to Die Hard | C662: 92000000 | D662: ['John Moore'] | E662: ['Skip Woods', 'Roderick Thorp'] | F662: ['Bruce Willis', 'Jai Courtney', 'Sebastian Koch'] | G662: 5.2 | H662: 2013 R 1h 38m | I662: 2013 | J662: 5.6666667 | K662: 6.6666667 | L662: 15.247936 | M662: =_xlfn.XLOOKUP(A662,Revenue!A:A,Revenue!C:C) -> 304249198
A663: xXx: Return of Xander Cage | B663: xXx: Return of Xander Cage | C663: 85000000 | D663: ['D.J. Caruso'] | E663: ['Rich Wilkes', 'F. Scott Frazier'] | F663: ['Vin Diesel', 'Donnie Yen', 'Deepika Padukone'] | G663: 5.2 | H663: 2017 PG-13 1h 47m | I663: 2017 | J663: 6.3333333 | K663: 4.8333333 | L663: 22.338954 | M663: =_xlfn.XLOOKUP(A663,Revenue!A:A,Revenue!C:C) -> 345033359
... A887: The Rhythm Section | B887: The Rhythm Section | C887: 50000000 | D887: ['Reed Morano'] | E887: ['Mark Burnell'] | F887: ['Blake Lively', 'Richard Brake', 'Elly Curtis'] | G887: 5.4 | H887: 2020 R 1h 49m | I887: 2020 | J887: 5 | K887: 5 | L887: 15.977525 | M887: =_xlfn.XLOOKUP(A887,Revenue!A:A,Revenue!C:C) -> 5983043
A888: 65 | B888: 65 | C888: 45000000 | D888: ['Scott Beck', 'Bryan Woods'] | E888: ['Scott Beck', 'Bryan Woods'] | F888: ['Adam Driver', 'Ariana Greenblatt', 'Chloe Coleman'] | G888: 5.4 | H888: 2023 PG-13 1h 33m | I888: 2023 | J888: 5 | K888: 6.6666667 | L888: 15.754391 | M888: =_xlfn.XLOOKUP(A888,Revenue!A:A,Revenue!C:C) -> 56241027
A889: Aliens in the Attic | B889: Aliens in the Attic | C889: 45000000 | D889: ['John Schultz'] | E889: ['Mark Burton', 'Adam F. Goldberg'] | F889: ['Ashley Tisdale', 'Robert Hoffman', 'Carter Jenkins'] | G889: 5.4 | H889: 2009 PG 1h 26m | I889: 2009 | J889: 5 | K889: 5.5 | L889: 17.52385 | M889: =_xlfn.XLOOKUP(A889,Revenue!A:A,Revenue!C:C) -> 59551283
A890: The Glimmer Man | B890: The Glimmer Man | C890: 45000000 | D890: ['John Gray'] | E890: ['Kevin Brodbin'] | F890: ['Steven Seagal', 'Keenen Ivory Wayans', 'Bob Gunton'] | G890: 5.4 | H890: 1996 R 1h 31m | I890: 1996 | J890: 5 | K890: 6 | L890: 9.3291128 | M890: =_xlfn.XLOOKUP(A890,Revenue!A:A,Revenue!C:C) -> 36404841
A891: Red Riding Hood | B891: Red Riding Hood | C891: 42000000 | D891: ['Catherine Hardwicke'] | E891: ['David Leslie Johnson-McGoldrick'] | F891: ['Amanda Seyfried', 'Lukas Haas', 'Gary Oldman'] | G891: 5.4 | H891: 2011 PG-13 1h 40m | I891: 2011 | J891: 6.3333333 | K891: 6.3333333 | L891: 11.033424 | M891: =_xlfn.XLOOKUP(A891,Revenue!A:A,Revenue!C:C) -> 91678442
A892: Get Rich or Die Tryin' | B892: Get Rich or Die Tryin' | C892: 40000000 | D892: ['Jim Sheridan'] | E892: ['Terence Winter'] | F892: ['50 Cent', 'Joy Bryant', 'Adewale Akinnuoye-Agbaje'] | G892: 5.4 | H892: 2005 R 1h 57m | I892: 2005 | J892: 6.3333333 | K892: 8 | L892: 15.495834 | M892: =_xlfn.XLOOKUP(A892,Revenue!A:A,Revenue!C:C) -> 46666955
A893: Season of the Witch | B893: Season of the Witch | C893: 40000000 | D893: ['Dominic Sena'] | E893: ['Bragi F. Schut'] | F893: ['Nicolas Cage', 'Ron Perlman', 'Claire Foy'] | G893: 5.4 | H893: 2011 PG-13 1h 35m | I893: 2011 | J893: 5.3333333 | K893: 5.5 | L893: 15.738688 | M893: =_xlfn.XLOOKUP(A893,Revenue!A:A,Revenue!C:C) -> 91126600
...

Sheet Revenue
A1: Movie Name | B1: Budget | C1: Revenue
A2: Avatar: The Way of Water | B2: 460000000 | C2: 2319591720
A3: Avengers: Endgame | B3: 400000000 | C3: 2788912285
A4: Pirates of the Caribbean: On Stranger Tides | B4: 379000000 | C4: 1045713802
A5: Avengers: Age of Ultron | B5: 365000000 | C5: 1395316979
A6: Fast X | B6: 340000000 | C6: 714414576
A7: Star Wars Ep. VII: The Force Awakens | B7: 306000000 | C7: 2064615817
A8: Avengers: Infinity War | B8: 300000000 | C8: 2048359754
A9: Pirates of the Caribbean: At World‚Äôs End | B9: 300000000 | C9: 960996492
A10: Justice League | B10: 300000000 | C10: 655945209
A11: Indiana Jones and the Dial of Destiny | B11: 300000000 | C11: 381561976
A12: Mission: Impossible Dead Reckoning Part One | B12: 290000000 | C12: 566325939
A13: Star Wars: The Rise of Skywalker | B13: 275000000 | C13: 1072767997
... A82: Black Adam | B82: 200000000 | C82: 390323855
A83: 2012 | B83: 200000000 | C83: 757677748
A84: Eternals | B84: 200000000 | C84: 401731759
A85: Fantastic Beasts: The Crimes of Grindelwald | B85: 200000000 | C85: 648455339
A86: Elemental | B86: 200000000 | C86: 486735727
A87: Terminator Salvation | B87: 200000000 | C87: 365491792
A88: Lightyear | B88: 200000000 | C88: 218768299
A89: Jungle Cruise | B89: 200000000 | C89: 210469803
A90: Green Lantern | B90: 200000000 | C90: 219535492
A91: The Flash | B91: 200000000 | C91: 266516138
A92: Fantastic Beasts: The Secrets of Dumbledore | B92: 200000000 | C92: 404560145
A93: Prince of Persia: Sands of Time | B93: 200000000 | C93: 336359676
A94: Killers of the Flower Moon | B94: 200000000 | C94: 154486520
A95: Dark Phoenix | B95: 200000000 | C95: 246356895
... A449: Django Unchained | B449: 100000000 | C449: 449841566
A450: 1917 | B450: 100000000 | C450: 389140440
A451: Little Fockers | B451: 100000000 | C451: 310650574
A452: True Lies | B452: 100000000 | C452: 365300000
A453: American Gangster | B453: 100000000 | C453: 267985456
A454: The Hunger Games: The Ballad of Songbirds & Snakes | B454: 100000000 | C454: 251950041
A455: Cloudy with a Chance of Meatballs | B455: 100000000 | C455: 236827677
A456: The Other Guys | B456: 100000000 | C456: 170936470
A457: Lemony Snicket's A Series of Unfortunate Events | B457: 100000000 | C457: 212956024
A458: The Wolf of Wall Street | B458: 100000000 | C458: 389816136
A459: Epic | B459: 100000000 | C459: 262794441
A460: Eraser | B460: 100000000 | C460: 234400000
A461: The Hunchback of Notre Dame | B461: 100000000 | C461: 325500000
...
